<?xml version="1.0"?>

<robot name="bumperbot" xmlns:xacro="http://ros.org/wiki/xacro">

  <!-- Start GZ or Ignition depending on ROS 2 Version -->
  <xacro:arg name="is_ignition" default="true"/>

  <!-- Load Simulated or Real Hardware Interfaces -->
  <xacro:arg name="is_sim" default="true"/>

  <!-- Include Gazebo Parameters -->
  <xacro:include filename="$(find bumperbot_description)/urdf/bumperbot_gazebo.xacro" />

  <!-- Include ros2_control Plugins -->
  <xacro:include filename="$(find bumperbot_description)/urdf/bumperbot_ros2_control.xacro" />

  <link name="base_footprint"/>
  
  <link name="base_link">
    <inertial>
      <origin xyz="0 0 0.04" rpy="0.0 0.25 0.3" />
      <mass value="250.0"/>
      <inertia ixx="2.2124416e-02" ixy="-1.2294101e-04" ixz="3.4938785e-04"
               iyy="2.1193702e-02" iyz="-5.0120904e-05"
               izz="2.0064271e-02" />
    </inertial>
    <visual>
      <origin xyz="0 0 0" rpy="0 0 0" />
      <geometry>
        <mesh filename="package://bumperbot_description/meshes/base_link_for_demo.stl" />
      </geometry>
      <material name="black"/>
    </visual>
    <collision>
      <origin xyz="0 0 0" rpy="0 0 0" />
      <geometry>
        <mesh filename="package://bumperbot_description/meshes/base_link_for_demo.stl" />
      </geometry>
    </collision>
  </link>

  <joint name="base_joint" type="fixed">
    <parent link="base_footprint"/>
    <child link="base_link" />
    <origin xyz="0 0 0.050" rpy="0 0 0"/>
  </joint>

  <link name="wheel_right1_link">
    <inertial>
      <origin xyz="0 -0.014 0" rpy="0 0 0" />
      <mass value="0.0530086090966721" />
      <inertia ixx="1.88176298336665E-05" ixy="-4.8444933029987E-10" ixz="1.88163708851143E-08"
               iyy="3.11510738647764E-05" iyz="-6.93560663069607E-11"
               izz="1.8801969558182E-05" />
    </inertial>
    <visual>
      <origin xyz="0 0 0" rpy="1.57 0 0" />
      <geometry>
        <mesh filename="package://bumperbot_description/meshes/wheel_right_link.STL" />
      </geometry>
      <material name="blue"/>
    </visual>
    <collision>
      <origin xyz="0 -0.015 0" rpy="1.57 0 0" />
      <geometry>
        <sphere radius="0.033"/>
      </geometry>
    </collision>
  </link>

  <joint name="wheel_right1_joint" type="continuous">
    <origin xyz="0.6 -0.6 -0.045" rpy="0 0 0" />
    <parent link="base_link" />
    <child link="wheel_right1_link" />
    <axis xyz="0 1 0" />
  </joint>
  
  <link
    name="wheel_left1_link">
    <inertial>
      <origin xyz="0 0.014 0" rpy="0 0 0" />
      <mass value="0.0530086043217644" />
      <inertia ixx="1.8792911368909E-05"  ixy="3.31256392204584E-10" ixz="-1.14082001662767E-08"
               iyy="3.11510738759073E-05" iyz="-3.60499245082192E-10"
               izz="1.88266886146847E-05" />
    </inertial>
    <visual>
      <origin xyz="0 0 0" rpy="-1.57 0 0" />
      <geometry>
        <mesh filename="package://bumperbot_description/meshes/wheel_left_link.STL" />
      </geometry>
      <material name="blue"/>
    </visual>
    <collision>
      <origin xyz="0 0.015 0" rpy="-1.57 0 0" />
      <geometry>
        <sphere radius="0.033"/>
      </geometry>
    </collision>
  </link>

  <joint name="wheel_left1_joint" type="continuous">
    <origin xyz="0.6 0.6 -0.045" rpy="0 0 0" />
    <parent link="base_link" />
    <child link="wheel_left1_link" />
    <axis xyz="0 1 0" />
  </joint>

  <link name="wheel_right2_link">
    <inertial>
      <origin xyz="0 -0.014 0" rpy="0 0 0" />
      <mass value="0.0530086090966721" />
      <inertia ixx="1.88176298336665E-05" ixy="-4.8444933029987E-10" ixz="1.88163708851143E-08"
               iyy="3.11510738647764E-05" iyz="-6.93560663069607E-11"
               izz="1.8801969558182E-05" />
    </inertial>
    <visual>
      <origin xyz="0 0 0" rpy="1.57 0 0" />
      <geometry>
        <mesh filename="package://bumperbot_description/meshes/wheel_right_link.STL" />
      </geometry>
      <material name="blue"/>
    </visual>
    <collision>
      <origin xyz="0 -0.015 0" rpy="1.57 0 0" />
      <geometry>
        <sphere radius="0.033"/>
      </geometry>
    </collision>
  </link>

  <joint name="wheel_right2_joint" type="continuous">
    <origin xyz="-0.6 -0.6 -0.045" rpy="0 0 0" />
    <parent link="base_link" />
    <child link="wheel_right2_link" />
    <axis xyz="0 1 0" />
  </joint>
  
  <link
    name="wheel_left2_link">
    <inertial>
      <origin xyz="0 0.014 0" rpy="0 0 0" />
      <mass value="0.0530086043217644" />
      <inertia ixx="1.8792911368909E-05"  ixy="3.31256392204584E-10" ixz="-1.14082001662767E-08"
               iyy="3.11510738759073E-05" iyz="-3.60499245082192E-10"
               izz="1.88266886146847E-05" />
    </inertial>
    <visual>
      <origin xyz="0 0 0" rpy="-1.57 0 0" />
      <geometry>
        <mesh filename="package://bumperbot_description/meshes/wheel_left_link.STL" />
      </geometry>
      <material name="blue"/>
    </visual>
    <collision>
      <origin xyz="0 0.015 0" rpy="-1.57 0 0" />
      <geometry>
        <sphere radius="0.033"/>
      </geometry>
    </collision>
  </link>

  <joint name="wheel_left2_joint" type="continuous">
    <origin xyz="-0.6 0.6 -0.045" rpy="0 0 0" />
    <parent link="base_link" />
    <child link="wheel_left2_link" />
    <axis xyz="0 1 0" />
  </joint>


  <link name="laser_link">
    <inertial>
      <origin xyz="-0.011945780406062 -0.000381929217680526 -0.0170649378129477" rpy="0 0 0" />
      <mass value="0.073084435549317" />
      <inertia ixx="1.96074931730795E-05" ixy="-3.62091076640009E-07" ixz="4.28230084046735E-07"
               iyy="2.40983835136327E-05" iyz="1.50180909250652E-08"
               izz="4.14184164228595E-05" />
    </inertial>
    <visual>
      <origin xyz="0 0 0" rpy="0 0 0" />
      <geometry>
        <mesh filename="package://bumperbot_description/meshes/laser_link.STL" />
      </geometry>
      <material name="dark_grey"/>
    </visual>
    <collision>
      <origin xyz="0 0 0" rpy="0 0 0" />
      <geometry>
        <mesh filename="package://bumperbot_description/meshes/laser_link.STL" />
      </geometry>
    </collision>
  </link>

  <joint name="laser_joint" type="fixed">
    <origin xyz="-0.0050526 -0.0023221 0.1208" rpy="0 0 3.14" />
    <parent link="base_link" />
    <child link="laser_link" />
    <axis xyz="0 0 0" />
  </joint>

  <material name="blue">
    <color rgba="0 0 1 1"/>
  </material>
  <material name="black">
    <color rgba="0 0 0 1"/>
  </material>
  <material name="silver">
    <color rgba="0.79 0.82 0.93 1"/>
  </material>
  <material name="dark_grey">
    <color rgba="0.3 0.3 0.3 1"/>
  </material>

</robot>